<?xml version="1.0" ?>
<robot xmlns:xacro="http://ros.org/wiki/xacro">
<xacro:macro name="motoman_motomini" params="prefix">
  <xacro:include filename="$(find motoman_resources)/urdf/common_materials.xacro"/>
  <xacro:prperty name ="PI" value="3.14152965359"/>
  <xacro:property name="effort" value="30.0" />
  <xacro:property name="velocity" value="10.0" />
  
  <!-- link list -->
  <link name="${prefix}base_link">
    <visual>
      <geometry>
        <mesh filename="package://yaskawa_description/meshes/motomini/visual/base_link.stl"/>
      </geometry>
      <xacro:material_yaskawa_blue/>
    </visual>
    <collision>
      <geometry>
        <mesh filename="package://yaskawa_description/meshes/motomini/collision/base_link.stl"/>
      </geometry>
    </collision>
  </link>
  <link name="${prefix}link_1_s">
    <visual>
      <geometry>
        <mesh filename="package://yaskawa_description/meshes/motomini/visual/link_1_s.stl"/>
      </geometry>
      <xacro:material_yaskawa_blue/>
    </visual>
    <collision>
      <geometry>
        <mesh filename="package://yaskawa_description/meshes/motomini/collision/link_1_s.stl"/>
      </geometry>
    </collision>
  </link>
  <link name="${prefix}link_2_l">
    <visual>
      <geometry>
        <mesh filename="package://yaskawa_description/meshes/motomini/visual/link_2_l.stl"/>
      </geometry>
      <xacro:material_yaskawa_blue/>
    </visual>
    <collision>
      <geometry>
        <mesh filename="package://yaskawa_description/meshes/motomini/collision/link_2_l.stl"/>
      </geometry>
    </collision>
  </link>
  <link name="${prefix}link_3_u">
    <visual>
      <geometry>
        <mesh filename="package://yaskawa_description/meshes/motomini/visual/link_3_u.stl"/>
      </geometry>
      <xacro:material_yaskawa_blue/>
    </visual>
    <collision>
      <geometry>
        <mesh filename="package://yaskawa_description/meshes/motomini/collision/link_3_u.stl"/>
      </geometry>
    </collision>
  </link>
  <link name="${prefix}link_4_r">
    <visual>
      <geometry>
        <mesh filename="package://yaskawa_description/meshes/motomini/visual/link_4_r.stl"/>
      </geometry>
      <xacro:material_yaskawa_blue/>
    </visual>
    <collision>
      <geometry>
        <mesh filename="package://yaskawa_description/meshes/motomini/collision/link_4_r.stl"/>
      </geometry>
    </collision>
  </link>
  <link name="${prefix}link_5_b">
    <visual>
      <geometry>
        <mesh filename="package://yaskawa_description/meshes/motomini/visual/link_5_b.stl"/>
      </geometry>
      <xacro:material_yaskawa_blue/>
    </visual>
    <collision>
      <geometry>
        <mesh filename="package://yaskawa_description/meshes/motomini/collision/link_5_b.stl"/>
      </geometry>
    </collision>
  </link>
  <link name="${prefix}link_6_t">
    <visual>
      <geometry>
        <mesh filename="package://yaskawa_description/meshes/motomini/visual/link_6_t.stl"/>
      </geometry>
      <xacro:material_yaskawa_blue/>
    </visual>
    <collision>
      <geometry>
        <mesh filename="package://yaskawa_description/meshes/motomini/collision/link_6_t.stl"/>
      </geometry>
    </collision>
  </link>
  <link name="claw_support">
    <xacro:default_inertial mass="0.05"/>
    <visual>
        <origin rpy="0 0 ${PI / 2}" xyz="0 -0.05 -0.15"/>
        <geometry>
            <mesh filename="package://dinnurobot_description/meshes/claw_support.STL" scale="0.01 0.01 0.01"/>
        </geometry>
    </visual>
    <collision>
        <origin rpy="0 0 ${PI / 2}" xyz="0 -0.05 -0.15"/>
        <geometry>
            <mesh filename="package://dinnurobot_description/meshes/claw_support.STL" scale="0.01 0.01 0.01"/>
        </geometry>
    </collision>
</link>
  <link name="gripper_right">
    <xacro:default_inertial mass="0.01"/>
    <visual>
        <origin rpy="0 0 -${PI / 2}" xyz="-0.1 0.50 -0.1"/>
        <geometry>
            <mesh filename="package://dinnurobot_description/meshes/right_finger.STL" scale="0.01 0.01 0.01"/>
        </geometry>
    </visual>
    <collision>
        <origin rpy="0 0 -${PI / 2}" xyz="-0.1 0.50 -0.1"/>
        <geometry>
            <mesh filename="package://dinnurobot_description/meshes/right_finger.STL" scale="0.01 0.01 0.01"/>
        </geometry>
    </collision>
</link>

<link name="gripper_left">
    <xacro:default_inertial mass="0.01"/>
    <visual>
        <origin rpy="0 0 -${PI / 2}" xyz="-0.04 0.50 -0.1"/>
        <geometry>
            <mesh filename="package://dinnurobot_description/meshes/left_finger.STL" scale="0.01 0.01 0.01"/>
        </geometry>
    </visual>
    <collision>
        <origin rpy="0 0 -${PI / 2}" xyz="-0.04 0.50 -0.1"/>
        <geometry>
            <mesh filename="package://dinnurobot_description/meshes/left_finger.STL" scale="0.01 0.01 0.01"/>
        </geometry>
    </collision>
</link>

<link name="rgb_camera">
    <xacro:default_inertial mass = "0.001"/>
    <visual>
        <origin rpy="-1.57 0 -1.57" xyz="-0.1 0.125 0.15"/>
        <geometry>
            <mesh filename="package://dinnurobot_description/meshes/pi_camera.STL" scale="0.01 0.01 0.01"/>
        </geometry>
    </visual>
    <collision>
        <origin rpy="-1.57 0 -1.57" xyz="-0.1 0.125 0.15"/>
        <geometry>
            <mesh filename="package://dinnurobot_description/meshes/pi_camera.STL" scale="0.01 0.01 0.01"/>
        </geometry>
    </collision>

    
  </link>
  
  <!-- end of link list -->

  <!-- joint list -->
  <joint name="${prefix}joint_1_s" type="revolute">
    <parent link="${prefix}base_link"/>
    <child link="${prefix}link_1_s"/>
    <origin xyz="0 0 0.103" rpy="0 0 0" />
    <axis xyz="0 0 1" />
    <limit lower="-2.9670" upper="2.9670" effort="0.12" velocity="5.4977"/>
  </joint>
  <joint name="${prefix}joint_2_l" type="revolute">
    <parent link="${prefix}link_1_s"/>
    <child link="${prefix}link_2_l"/>
    <origin xyz="0.020 0 0" rpy="0 0 0" />
    <axis xyz="0 1 0" />
    <limit lower="-1.4835" upper="1.5707" effort="0.12" velocity="5.4977"/>
  </joint>
  <joint name="${prefix}joint_3_u" type="revolute">
    <parent link="${prefix}link_2_l"/>
    <child link="${prefix}link_3_u"/>
    <origin xyz="0 0 0.165" rpy="0 0 0" />
    <axis xyz="0 -1 0" />
    <limit lower="-0.8726" upper="1.5707" effort="0.12" velocity="7.3304"/>
  </joint>
  <joint name="${prefix}joint_4_r" type="revolute">
    <parent link="${prefix}link_3_u"/>
    <child link="${prefix}link_4_r"/>
    <origin xyz="0.165 0 0" rpy="0 0 0" />
    <axis xyz="-1 0 0" />
    <limit lower="-2.4434" upper="2.4434" effort="0.07" velocity="10.4719"/>
  </joint>
  <joint name="${prefix}joint_5_b" type="revolute">
    <parent link="${prefix}link_4_r"/>
    <child link="${prefix}link_5_b"/>
    <origin xyz="0 0 0" rpy="0 0 0" />
    <axis xyz="0 -1 0" />
    <limit lower="-0.5235" upper="3.6651" effort="0.07" velocity="10.4719"/>
  </joint>
  <joint name="${prefix}joint_6_t" type="revolute">
    <parent link="${prefix}link_5_b"/>
    <child link="${prefix}link_6_t"/>
    <origin xyz="0 0 0" rpy="0 0 0" />
    <axis xyz="0 0 1" />
    <limit lower="-6.2831" upper="6.2831" effort="0.07" velocity="10.4719"/>
  </joint>
  <joint name="claw_support_joint" type="fixed">
    <origin xyz="0 0 -0.040 " rpy="${pi} 0 0"/>
    <parent link="${prefix}link_6_t"/>
    <child link="claw_support"/>
  </joint>
  <joint name="joint_7" type="revolute">
    <origin xyz="0 0 -0.040 " rpy="${pi} 0 0"/>
    <parent link="claw_support"/>
    <child link="gripper_right"/>
    <axis xyz="0 0 1"/>
    <limit lower="-${PI / 2}" upper="0.0" effort="${effort}" velocity="${velocity}"/>
  </joint>
  <joint name="joint_8" type="revolute">
    <origin xyz="0 0 -0.040 " rpy="${pi} 0 0"/>
    <parent link="claw_support"/>
    <child link="gripper_left"/>
    <axis xyz="0 0 1"/>
    <limit lower="0.0" upper="${PI / 2}" effort="${effort}" velocity="${velocity}"/>
    <mimic joint="joint_4" multiplier="-1"/>
  </joint>

  <!-- end of joint list -->

  <!-- ROS base_link to Robot Manufacturer World Coordinates transform -->
  <link name="${prefix}base" />
  <joint name="${prefix}base_link-base" type="fixed">
    <origin xyz="0 0 0.103" rpy="0 0 0"/>
    <parent link="${prefix}base_link"/>
    <child link="${prefix}base"/>
  </joint>

  </xacro:macro>
</robot>
